Exception on /users/authenticate [POST]
Traceback (most recent call last):
  File "D:\Anaconda3\lib\site-packages\flask\app.py", line 1982, in wsgi_app
    response = self.full_dispatch_request()
  File "D:\Anaconda3\lib\site-packages\flask\app.py", line 1614, in full_dispatch_request
    rv = self.handle_user_exception(e)
  File "D:\Anaconda3\lib\site-packages\flask_cors\extension.py", line 161, in wrapped_function
    return cors_after_request(app.make_response(f(*args, **kwargs)))
  File "D:\Anaconda3\lib\site-packages\flask\app.py", line 1517, in handle_user_exception
    reraise(exc_type, exc_value, tb)
  File "D:\Anaconda3\lib\site-packages\flask\_compat.py", line 33, in reraise
    raise value
  File "D:\Anaconda3\lib\site-packages\flask\app.py", line 1612, in full_dispatch_request
    rv = self.dispatch_request()
  File "D:\Anaconda3\lib\site-packages\flask\app.py", line 1598, in dispatch_request
    return self.view_functions[rule.endpoint](**req.view_args)
  File "app.py", line 209, in users_authenticate
    session['logged_in'] = True
  File "D:\Anaconda3\lib\site-packages\werkzeug\local.py", line 350, in __setitem__
    self._get_current_object()[key] = value
  File "D:\Anaconda3\lib\site-packages\flask\sessions.py", line 130, in _fail
    raise RuntimeError('The session is unavailable because no secret '
RuntimeError: The session is unavailable because no secret key was set.  Set the secret_key on the application to something unique and secret.
Exception on /users/register [GET]
Traceback (most recent call last):
  File "D:\Anaconda3\lib\site-packages\flask\app.py", line 1982, in wsgi_app
    response = self.full_dispatch_request()
  File "D:\Anaconda3\lib\site-packages\flask\app.py", line 1614, in full_dispatch_request
    rv = self.handle_user_exception(e)
  File "D:\Anaconda3\lib\site-packages\flask_cors\extension.py", line 161, in wrapped_function
    return cors_after_request(app.make_response(f(*args, **kwargs)))
  File "D:\Anaconda3\lib\site-packages\flask\app.py", line 1517, in handle_user_exception
    reraise(exc_type, exc_value, tb)
  File "D:\Anaconda3\lib\site-packages\flask\_compat.py", line 33, in reraise
    raise value
  File "D:\Anaconda3\lib\site-packages\flask\app.py", line 1612, in full_dispatch_request
    rv = self.dispatch_request()
  File "D:\Anaconda3\lib\site-packages\flask\app.py", line 1598, in dispatch_request
    return self.view_functions[rule.endpoint](**req.view_args)
  File "app.py", line 182, in users_register
    return render_template('register.html', form=form)
NameError: name 'form' is not defined
Exception on /users/authenticate [POST]
Traceback (most recent call last):
  File "D:\Anaconda3\lib\site-packages\flask\app.py", line 1982, in wsgi_app
    response = self.full_dispatch_request()
  File "D:\Anaconda3\lib\site-packages\flask\app.py", line 1614, in full_dispatch_request
    rv = self.handle_user_exception(e)
  File "D:\Anaconda3\lib\site-packages\flask_cors\extension.py", line 161, in wrapped_function
    return cors_after_request(app.make_response(f(*args, **kwargs)))
  File "D:\Anaconda3\lib\site-packages\flask\app.py", line 1517, in handle_user_exception
    reraise(exc_type, exc_value, tb)
  File "D:\Anaconda3\lib\site-packages\flask\_compat.py", line 33, in reraise
    raise value
  File "D:\Anaconda3\lib\site-packages\flask\app.py", line 1612, in full_dispatch_request
    rv = self.dispatch_request()
  File "D:\Anaconda3\lib\site-packages\flask\app.py", line 1598, in dispatch_request
    return self.view_functions[rule.endpoint](**req.view_args)
  File "app.py", line 205, in users_authenticate
    password = result['password']
TypeError: list indices must be integers or slices, not str
[('$5$rounds=535000$NFWbv9hFz9I0LIDd$/wZLrB18XMS/SYBBZdtLa1o8ha1QhIiBwnFjjb3fNT6',)]
('$5$rounds=535000$NFWbv9hFz9I0LIDd$/wZLrB18XMS/SYBBZdtLa1o8ha1QhIiBwnFjjb3fNT6',)
user4 logged in successfully. token = 715600eb-6e6c-4fff-9006-ed7a6e53e2d8
user1 logged in successfully. token = 9fc4b9dd-5458-43a4-9b2d-87223642e7a8
user3 logged in successfully. token = 236a216b-2eed-44a2-a391-dc822500330e
user1 logged in successfully. token = 63ebf58e-dfe2-419f-8a2e-e1681c057094
